[2023-05-24 15:33:06,724] / ERROR 
(<class 'kombu.exceptions.OperationalError'>, OperationalError('Error 11001 connecting to redis-12164.c55.eu-central-1-1.ec2.cloud.redislabs.com:12164. getaddrinfo failed.'), <traceback object at 0x00000135B7D86580>) 
E:\Skillfactory\Repositories\NewsPortal\News_Portal\venv\lib\site-packages\django\utils\log.py 
Internal Server Error: /news/create/ 
Traceback (most recent call last):
  File "E:\Skillfactory\Repositories\NewsPortal\News_Portal\venv\lib\site-packages\redis\connection.py", line 698, in connect
    sock = self.retry.call_with_retry(
  File "E:\Skillfactory\Repositories\NewsPortal\News_Portal\venv\lib\site-packages\redis\retry.py", line 46, in call_with_retry
    return do()
  File "E:\Skillfactory\Repositories\NewsPortal\News_Portal\venv\lib\site-packages\redis\connection.py", line 699, in <lambda>
    lambda: self._connect(), lambda error: self.disconnect(error)
  File "E:\Skillfactory\Repositories\NewsPortal\News_Portal\venv\lib\site-packages\redis\connection.py", line 955, in _connect
    for res in socket.getaddrinfo(
  File "C:\Users\Иван\AppData\Local\Programs\Python\Python310\lib\socket.py", line 955, in getaddrinfo
    for res in _socket.getaddrinfo(host, port, family, type, proto, flags):
socket.gaierror: [Errno 11001] getaddrinfo failed

During handling of the above exception, another exception occurred:

Traceback (most recent call last):
  File "E:\Skillfactory\Repositories\NewsPortal\News_Portal\venv\lib\site-packages\celery\backends\redis.py", line 119, in reconnect_on_error
    yield
  File "E:\Skillfactory\Repositories\NewsPortal\News_Portal\venv\lib\site-packages\celery\backends\redis.py", line 169, in _consume_from
    self._pubsub.subscribe(key)
  File "E:\Skillfactory\Repositories\NewsPortal\News_Portal\venv\lib\site-packages\redis\client.py", line 1623, in subscribe
    ret_val = self.execute_command("SUBSCRIBE", *new_channels.keys())
  File "E:\Skillfactory\Repositories\NewsPortal\News_Portal\venv\lib\site-packages\redis\client.py", line 1458, in execute_command
    self.connection = self.connection_pool.get_connection(
  File "E:\Skillfactory\Repositories\NewsPortal\News_Portal\venv\lib\site-packages\redis\connection.py", line 1442, in get_connection
    connection.connect()
  File "E:\Skillfactory\Repositories\NewsPortal\News_Portal\venv\lib\site-packages\redis\connection.py", line 704, in connect
    raise ConnectionError(self._error_message(e))
redis.exceptions.ConnectionError: Error 11001 connecting to redis-12164.c55.eu-central-1-1.ec2.cloud.redislabs.com:12164. getaddrinfo failed.

During handling of the above exception, another exception occurred:

Traceback (most recent call last):
  File "E:\Skillfactory\Repositories\NewsPortal\News_Portal\venv\lib\site-packages\redis\connection.py", line 698, in connect
    sock = self.retry.call_with_retry(
  File "E:\Skillfactory\Repositories\NewsPortal\News_Portal\venv\lib\site-packages\redis\retry.py", line 46, in call_with_retry
    return do()
  File "E:\Skillfactory\Repositories\NewsPortal\News_Portal\venv\lib\site-packages\redis\connection.py", line 699, in <lambda>
    lambda: self._connect(), lambda error: self.disconnect(error)
  File "E:\Skillfactory\Repositories\NewsPortal\News_Portal\venv\lib\site-packages\redis\connection.py", line 955, in _connect
    for res in socket.getaddrinfo(
  File "C:\Users\Иван\AppData\Local\Programs\Python\Python310\lib\socket.py", line 955, in getaddrinfo
    for res in _socket.getaddrinfo(host, port, family, type, proto, flags):
socket.gaierror: [Errno 11001] getaddrinfo failed

During handling of the above exception, another exception occurred:

Traceback (most recent call last):
  File "E:\Skillfactory\Repositories\NewsPortal\News_Portal\venv\lib\site-packages\kombu\connection.py", line 446, in _reraise_as_library_errors
    yield
  File "E:\Skillfactory\Repositories\NewsPortal\News_Portal\venv\lib\site-packages\celery\app\base.py", line 787, in send_task
    self.backend.on_task_call(P, task_id)
  File "E:\Skillfactory\Repositories\NewsPortal\News_Portal\venv\lib\site-packages\celery\backends\redis.py", line 365, in on_task_call
    self.result_consumer.consume_from(task_id)
  File "E:\Skillfactory\Repositories\NewsPortal\News_Portal\venv\lib\site-packages\celery\backends\redis.py", line 161, in consume_from
    return self.start(task_id)
  File "E:\Skillfactory\Repositories\NewsPortal\News_Portal\venv\lib\site-packages\celery\backends\redis.py", line 139, in start
    self._consume_from(initial_task_id)
  File "E:\Skillfactory\Repositories\NewsPortal\News_Portal\venv\lib\site-packages\celery\backends\redis.py", line 168, in _consume_from
    with self.reconnect_on_error():
  File "C:\Users\Иван\AppData\Local\Programs\Python\Python310\lib\contextlib.py", line 153, in __exit__
    self.gen.throw(typ, value, traceback)
  File "E:\Skillfactory\Repositories\NewsPortal\News_Portal\venv\lib\site-packages\celery\backends\redis.py", line 122, in reconnect_on_error
    self._ensure(self._reconnect_pubsub, ())
  File "E:\Skillfactory\Repositories\NewsPortal\News_Portal\venv\lib\site-packages\celery\backends\redis.py", line 376, in ensure
    return retry_over_time(
  File "E:\Skillfactory\Repositories\NewsPortal\News_Portal\venv\lib\site-packages\kombu\utils\functional.py", line 312, in retry_over_time
    return fun(*args, **kwargs)
  File "E:\Skillfactory\Repositories\NewsPortal\News_Portal\venv\lib\site-packages\celery\backends\redis.py", line 106, in _reconnect_pubsub
    metas = self.backend.client.mget(self.subscribed_to)
  File "E:\Skillfactory\Repositories\NewsPortal\News_Portal\venv\lib\site-packages\redis\commands\core.py", line 1976, in mget
    return self.execute_command("MGET", *args, **options)
  File "E:\Skillfactory\Repositories\NewsPortal\News_Portal\venv\lib\site-packages\redis\client.py", line 1255, in execute_command
    conn = self.connection or pool.get_connection(command_name, **options)
  File "E:\Skillfactory\Repositories\NewsPortal\News_Portal\venv\lib\site-packages\redis\connection.py", line 1442, in get_connection
    connection.connect()
  File "E:\Skillfactory\Repositories\NewsPortal\News_Portal\venv\lib\site-packages\redis\connection.py", line 704, in connect
    raise ConnectionError(self._error_message(e))
redis.exceptions.ConnectionError: Error 11001 connecting to redis-12164.c55.eu-central-1-1.ec2.cloud.redislabs.com:12164. getaddrinfo failed.

The above exception was the direct cause of the following exception:

Traceback (most recent call last):
  File "E:\Skillfactory\Repositories\NewsPortal\News_Portal\venv\lib\site-packages\django\core\handlers\exception.py", line 56, in inner
    response = get_response(request)
  File "E:\Skillfactory\Repositories\NewsPortal\News_Portal\venv\lib\site-packages\django\core\handlers\base.py", line 197, in _get_response
    response = wrapped_callback(request, *callback_args, **callback_kwargs)
  File "E:\Skillfactory\Repositories\NewsPortal\News_Portal\venv\lib\site-packages\django\views\generic\base.py", line 103, in view
    return self.dispatch(request, *args, **kwargs)
  File "E:\Skillfactory\Repositories\NewsPortal\News_Portal\venv\lib\site-packages\django\contrib\auth\mixins.py", line 73, in dispatch
    return super().dispatch(request, *args, **kwargs)
  File "E:\Skillfactory\Repositories\NewsPortal\News_Portal\venv\lib\site-packages\django\contrib\auth\mixins.py", line 109, in dispatch
    return super().dispatch(request, *args, **kwargs)
  File "E:\Skillfactory\Repositories\NewsPortal\News_Portal\venv\lib\site-packages\django\views\generic\base.py", line 142, in dispatch
    return handler(request, *args, **kwargs)
  File "E:\Skillfactory\Repositories\NewsPortal\News_Portal\venv\lib\site-packages\django\views\generic\edit.py", line 184, in post
    return super().post(request, *args, **kwargs)
  File "E:\Skillfactory\Repositories\NewsPortal\News_Portal\venv\lib\site-packages\django\views\generic\edit.py", line 153, in post
    return self.form_valid(form)
  File "E:\Skillfactory\Repositories\NewsPortal\News_Portal\News\views.py", line 108, in form_valid
    return super().form_valid(form)
  File "E:\Skillfactory\Repositories\NewsPortal\News_Portal\venv\lib\site-packages\django\views\generic\edit.py", line 135, in form_valid
    self.object = form.save()
  File "E:\Skillfactory\Repositories\NewsPortal\News_Portal\venv\lib\site-packages\django\forms\models.py", line 549, in save
    self._save_m2m()
  File "E:\Skillfactory\Repositories\NewsPortal\News_Portal\venv\lib\site-packages\django\forms\models.py", line 530, in _save_m2m
    f.save_form_data(self.instance, cleaned_data[f.name])
  File "E:\Skillfactory\Repositories\NewsPortal\News_Portal\venv\lib\site-packages\django\db\models\fields\related.py", line 1963, in save_form_data
    getattr(instance, self.attname).set(data)
  File "E:\Skillfactory\Repositories\NewsPortal\News_Portal\venv\lib\site-packages\django\db\models\fields\related_descriptors.py", line 1169, in set
    self.add(*new_objs, through_defaults=through_defaults)
  File "E:\Skillfactory\Repositories\NewsPortal\News_Portal\venv\lib\site-packages\django\db\models\fields\related_descriptors.py", line 1087, in add
    self._add_items(
  File "E:\Skillfactory\Repositories\NewsPortal\News_Portal\venv\lib\site-packages\django\db\models\fields\related_descriptors.py", line 1373, in _add_items
    signals.m2m_changed.send(
  File "E:\Skillfactory\Repositories\NewsPortal\News_Portal\venv\lib\site-packages\django\dispatch\dispatcher.py", line 176, in send
    return [
  File "E:\Skillfactory\Repositories\NewsPortal\News_Portal\venv\lib\site-packages\django\dispatch\dispatcher.py", line 177, in <listcomp>
    (receiver, receiver(signal=self, sender=sender, **named))
  File "E:\Skillfactory\Repositories\NewsPortal\News_Portal\News\signals.py", line 10, in notify_new_post
    notify_new_post_with_celery.apply_async([instance.pk], countdown=10)
  File "E:\Skillfactory\Repositories\NewsPortal\News_Portal\venv\lib\site-packages\celery\app\task.py", line 575, in apply_async
    return app.send_task(
  File "E:\Skillfactory\Repositories\NewsPortal\News_Portal\venv\lib\site-packages\celery\app\base.py", line 785, in send_task
    with P.connection._reraise_as_library_errors():
  File "C:\Users\Иван\AppData\Local\Programs\Python\Python310\lib\contextlib.py", line 153, in __exit__
    self.gen.throw(typ, value, traceback)
  File "E:\Skillfactory\Repositories\NewsPortal\News_Portal\venv\lib\site-packages\kombu\connection.py", line 450, in _reraise_as_library_errors
    raise ConnectionError(str(exc)) from exc
kombu.exceptions.OperationalError: Error 11001 connecting to redis-12164.c55.eu-central-1-1.ec2.cloud.redislabs.com:12164. getaddrinfo failed.
[2023-05-24 15:33:06,753] / ERROR 
None 
E:\Skillfactory\Repositories\NewsPortal\News_Portal\venv\lib\site-packages\django\core\servers\basehttp.py 
"POST /news/create/ HTTP/1.1" 500 324165 

